<robot name="scorpion">
    <material name="base_color">
        <color rgba="0.4902 0.0863 0.5569 1"/>
    </material>

    <material name="arm1_color">
        <color rgba="0.6824 0.3333 0.7373 1"/>
    </material>

    <material name="arm2_color">
        <color rgba="0.5137 0.4157 0.7333 1"/>
    </material>

    <material name="arm3_color">
        <color rgba="0.3686 0.2510 0.6431 1"/>
    </material>

    <material name="end_effector_color">
        <color rgba="0.2902 0.1294 0.9373 1"/>
    </material>

    <material name="intake_color">
        <color rgba="0.9804 0.7137 0.0 1"/>
    </material>

    <material name="wheel_color">
        <color rgba="0.0627 0.2667 0.4902 1"/>
    </material>


    <link name="base_tilt_link">
        <visual>
            <origin xyz="0 0 0" rpy="0 0 0"/>
            <geometry>
                <mesh filename="package://tj2_description/meshes/scorpion/base.stl"/>
            </geometry>
            <material name="base_color"/>
        </visual>
    </link>

    <link name="arm1_base_link"/>

    <link name="arm1_link">
        <visual>
            <origin xyz="0 0 0" rpy="0 0 0"/>
            <geometry>
                <mesh filename="package://tj2_description/meshes/scorpion/arm1.stl"/>
            </geometry>
            <material name="arm1_color"/>
        </visual>
    </link>

    <link name="arm2_base_link"/>

    <link name="arm2_link">
        <visual>
            <origin xyz="0 0 0" rpy="0 0 0"/>
            <geometry>
                <mesh filename="package://tj2_description/meshes/scorpion/arm2.stl"/>
            </geometry>
            <material name="arm2_color"/>
        </visual>
    </link>

    <link name="arm3_base_link"/>

    <link name="arm3_link">
        <visual>
            <origin xyz="0 0 0" rpy="0 0 0"/>
            <geometry>
                <mesh filename="package://tj2_description/meshes/scorpion/arm3.stl"/>
            </geometry>
            <material name="arm3_color"/>
        </visual>
    </link>

    <link name="end_effector_base_link"/>

    <link name="end_effector_link">
        <visual>
            <origin xyz="0 0 0" rpy="0 0 0"/>
            <geometry>
                <mesh filename="package://tj2_description/meshes/scorpion/end_effector.stl"/>
            </geometry>
            <material name="end_effector_color"/>
        </visual>
    </link>

    <link name="intake_base_link"/>

    <link name="intake_link">
        <visual>
            <origin xyz="0 0 0" rpy="0 0 0"/>
            <geometry>
                <mesh filename="package://tj2_description/meshes/scorpion/intake.stl"/>
            </geometry>
            <material name="intake_color"/>
        </visual>
    </link>

    <link name="swerve_wheel_0">
        <visual>
            <origin xyz="0 0 0" rpy="0 0 0"/>
            <geometry>
                <mesh filename="package://tj2_description/meshes/scorpion/wheel.stl"/>
            </geometry>
            <material name="wheel_color"/>
        </visual>
    </link>

    <link name="swerve_wheel_1">
        <visual>
            <origin xyz="0 0 0" rpy="0 0 0"/>
            <geometry>
                <mesh filename="package://tj2_description/meshes/scorpion/wheel.stl"/>
            </geometry>
            <material name="wheel_color"/>
        </visual>
    </link>

    <link name="swerve_wheel_2">
        <visual>
            <origin xyz="0 0 0" rpy="0 0 0"/>
            <geometry>
                <mesh filename="package://tj2_description/meshes/scorpion/wheel.stl"/>
            </geometry>
            <material name="wheel_color"/>
        </visual>
    </link>

    <link name="swerve_wheel_3">
        <visual>
            <origin xyz="0 0 0" rpy="0 0 0"/>
            <geometry>
                <mesh filename="package://tj2_description/meshes/scorpion/wheel.stl"/>
            </geometry>
            <material name="wheel_color"/>
        </visual>
    </link>

    <!-- Joint definitions -->

    <!-- Arms joints -->


    <joint name="base_to_arm1_base_link" type="fixed">
        <parent link="base_tilt_link"/>
        <child link="arm1_base_link"/>
        <origin xyz="-0.26670  0.25129  0.46994"
                rpy="0.0  0.0  0.0"/>
    </joint>

    <joint name="arm1_base_to_arm1_link" type="continuous">
        <parent link="arm1_base_link"/>
        <child link="arm1_link"/>
        <origin xyz="0.0  0.0  0.0"
                rpy="1.570796  0.0  0.0"/>
        <axis xyz="0 0 1"/>
    </joint>

    <joint name="arm1_to_arm2_base_link" type="fixed">
        <parent link="arm1_link"/>
        <child link="arm2_base_link"/>
        <origin xyz="0.49530  0.0  0.0"
                rpy="0.0  0.0  0.0"/>
    </joint>

    <joint name="arm2_base_to_arm2_link" type="continuous">
        <parent link="arm2_base_link"/>
        <child link="arm2_link"/>
        <origin xyz="0.0  0.0  0.0"
                rpy="0.0  0.0  0.0"/>
        <axis xyz="0 0 1"/>
    </joint>

    <joint name="arm2_to_arm3_base_link" type="fixed">
        <parent link="arm2_link"/>
        <child link="arm3_base_link"/>
        <origin xyz="0.39370  0.0  0.1"
                rpy="0.0  0.0  0.0"/>
    </joint>

    <joint name="arm3_base_to_arm3_link" type="continuous">
        <parent link="arm3_base_link"/>
        <child link="arm3_link"/>
        <origin xyz="0.0  0.0  0.0"
                rpy="0.0  0.0  0.0"/>
        <axis xyz="0 0 1"/>
    </joint>

    <joint name="arm3_to_end_effector_base_link" type="fixed">
        <parent link="arm3_link"/>
        <child link="end_effector_base_link"/>
        <origin xyz="0.17165  0.0  0.21110"
                rpy="0.0  0.0  0.0"/>
    </joint>

    <joint name="end_effector_base_to_end_effector_link" type="continuous">
        <parent link="end_effector_base_link"/>
        <child link="end_effector_link"/>
        <origin xyz="0.0  0.0  0.0"
                rpy="1.570796  0.0  1.570796"/>
        <axis xyz="0 0 1"/>
    </joint>

    <!-- Intake joints -->

    <joint name="base_to_intake_base_link" type="fixed">
        <parent link="base_tilt_link"/>
        <child link="intake_base_link"/>
        <origin xyz="0.24765  0.0  0.12070"
                rpy="0.0  0.0  0.0"/>
    </joint>

    <joint name="intake_base_to_intake_link" type="continuous">
        <parent link="intake_base_link"/>
        <child link="intake_link"/>
        <origin xyz="0.0  0.0  0.0"
                rpy="0.0  -1.570796  -1.570796"/>
        <axis xyz="0 0 1"/>
    </joint>

    <!-- Wheel joints -->

    <joint name="base_link_to_wheel_0_joint" type="continuous">
        <parent link="base_tilt_link"/>
        <child link="swerve_wheel_0"/>
        <origin xyz="0.27623  0.27623  0.05079"/>
        <axis xyz="0 0 1"/>
    </joint>

    <joint name="base_link_to_wheel_1_joint" type="continuous">
        <parent link="base_tilt_link"/>
        <child link="swerve_wheel_1"/>
        <origin xyz="-0.27623  0.27623  0.05079"/>
        <axis xyz="0 0 1"/>
    </joint>
    
    <joint name="base_link_to_wheel_2_joint" type="continuous">
        <parent link="base_tilt_link"/>
        <child link="swerve_wheel_2"/>
        <origin xyz="-0.27623  -0.27623  0.05079"/>
        <axis xyz="0 0 1"/>
    </joint>

    <joint name="base_link_to_wheel_3_joint" type="continuous">
        <parent link="base_tilt_link"/>
        <child link="swerve_wheel_3"/>
        <origin xyz="0.27623  -0.27623  0.05079"/>
        <axis xyz="0 0 1"/>
    </joint>
</robot>
