<robot name="diffyjr">
    <material name="white">
        <color rgba="1 1 1 1"/>
    </material>

    <material name="blue">
        <color rgba="0 0.369 0.722 1"/>
    </material>

    <material name="red">
        <color rgba="0.722 0.369 0 1"/>
    </material>

    <link name="base_link">
    </link>

    <joint name="base_link_to_roll" type="continuous">
        <parent link="base_link"/>
        <child link="base_roll"/>
        <origin xyz="0.0  0.0  0.0" rpy="0 0 0"/>
        <axis xyz="0 1 0"/>
    </joint>

    <link name="base_roll">
    </link>

    <joint name="base_roll_to_pitch" type="continuous">
        <parent link="base_roll"/>
        <child link="base_pitch"/>
        <origin xyz="0.0  0.0  0.0" rpy="0 0 0"/>
        <axis xyz="1 0 0"/>
    </joint>

    <link name="base_pitch">
    </link>

    <joint name="base_pitch_to_footprint" type="fixed">
        <parent link="base_pitch"/>
        <child link="base_footprint"/>
        <origin xyz="0 0 0"/>
    </joint>

    <link name="base_footprint">
        <visual>
            <origin xyz="0 0 0.117" rpy="0 0 1.57"/>
            <geometry>
                <mesh filename="package://tj2_description/meshes/diffyjr/chassis.stl"/>
            </geometry>
            <material name="blue"/>
        </visual>
    </link>

    <link name="swerve_wheel_0">
        <visual>
            <origin xyz="0 0 0" rpy="0 0 0"/>
            <geometry>
                <mesh filename="package://tj2_description/meshes/diffyjr/wheel.stl"/>
            </geometry>
            <material name="red"/>
        </visual>
    </link>

    <link name="swerve_wheel_1">
        <visual>
            <origin xyz="0 0 0" rpy="0 0 0"/>
            <geometry>
                <mesh filename="package://tj2_description/meshes/diffyjr/wheel.stl"/>
            </geometry>
            <material name="red"/>
        </visual>
    </link>

    <link name="swerve_wheel_2">
        <visual>
            <origin xyz="0 0 0" rpy="0 0 0"/>
            <geometry>
                <mesh filename="package://tj2_description/meshes/diffyjr/wheel.stl"/>
            </geometry>
            <material name="red"/>
        </visual>
    </link>

    <link name="swerve_wheel_3">
        <visual>
            <origin xyz="0 0 0" rpy="0 0 0"/>
            <geometry>
                <mesh filename="package://tj2_description/meshes/diffyjr/wheel.stl"/>
            </geometry>
            <material name="red"/>
        </visual>
    </link>

    <joint name="base_link_to_wheel_0_joint" type="continuous">
        <parent link="base_footprint"/>
        <child link="swerve_wheel_0"/>
        <origin xyz="0.154305  0.154305  0.044"/>
        <axis xyz="0 0 1"/>
    </joint>

    <joint name="base_link_to_wheel_1_joint" type="continuous">
        <parent link="base_footprint"/>
        <child link="swerve_wheel_1"/>
        <origin xyz="-0.154305  0.154305  0.044"/>
        <axis xyz="0 0 1"/>
    </joint>
    
    <joint name="base_link_to_wheel_2_joint" type="continuous">
        <parent link="base_footprint"/>
        <child link="swerve_wheel_2"/>
        <origin xyz="-0.154305  -0.154305  0.044"/>
        <axis xyz="0 0 1"/>
    </joint>

    <joint name="base_link_to_wheel_3_joint" type="continuous">
        <parent link="base_footprint"/>
        <child link="swerve_wheel_3"/>
        <origin xyz="0.154305  -0.154305  0.044"/>
        <axis xyz="0 0 1"/>
    </joint>
    
</robot>
